Workbook

Sheet Citas New New
C1: Region | D1: Owner Name | E1: Subject | F1: Account Legal Name | G1: Top Parent Account | H1: Date | I1: Comments | J1: Top Parent | K1: New New | L1: Last Date | M1: Diferencia de dias | N1: Last Owner | O1: Last Región | P1: Account status | Q1: Validación Owner | R1: Tiempo | S1: Owner de la cuenta | T1: Validación Owner-Cuenta-Cita | U1: Estado | V1: EXT_REF_ID | W1: Total exposure | X1: Industry
C2: =VLOOKUP(D2,Diccionario!A:B,2,0) -> Estructurados Core | D2: Fernanda Rangel | E2: Meeting | F2: Omnibus Unidos Regiomontanos | H2: 46078 | I2: Se platicó con la empresa, el nombre comercial es APOLO, tienen viajes nacionales, e incursionan tambien en paquetería, compraron camiones y se los entregaron este diciembre 2025, el cliente tiene créditos caros, por lo que se buscará un refinanciamiento, cada camiones vale enre 8 y 12 mdp, los de ellos, al comprarlos doble piso valen 12 mdp, compran anualmente entre 4 y 5 camiones. Se pidió el listado de activos y el cuadro de pasivos. 40 camiones. Marca Volvo: Doubledeckers. Se financia con SOFOMS: Unifin, y locales. Volvo financial. Tasa calcula all in. 60 meses. Pains: Financiamientos con costo alto. Se detectó que hay oportunidad de refinanciamiento. No se proporcionó información de saldos, ni plazos remanentes. Objeciones: Booth Collateral. | J2: =IF(G2="",F2,G2) -> Omnibus Unidos Regiomontanos | K2: =IFERROR(VLOOKUP(Table1[[#This Row],[Top Parent]],'1.- Citas sin this week'!G:G,1,0),"New New") -> New New | L2: =_xlfn.XLOOKUP(Table1[[#This Row],[Top Parent]],Table3[Top Parent],Table3[Date]) -> #N/A | M2: =Table1[[#This Row],[Date]]-Table1[[#This Row],[Last Date]] -> #N/A | N2: =_xlfn.XLOOKUP(Table1[[#This Row],[Top Parent]],Table3[Top Parent],Table3[Owner Name]) -> #N/A | Q2: =IF(Table1[[#This Row],[Last Owner]]=Table1[[#This Row],[Owner Name]],"No","Si") -> #N/A | R2: =IF(Table1[[#This Row],[Diferencia de dias]]>182,"Si","No") -> #N/A | S2: Fernanda Rangel | T2: =IF(Table1[[#This Row],[Owner de la cuenta]]=Table1[[#This Row],[Owner Name]],"Si","No") -> Si | U2: Nuevo León | V2: SFAC0006110894 | X2: Transportation
C3: =VLOOKUP(D3,Diccionario!A:B,2,0) -> Estructurados Core | D3: Fernanda Rangel | E3: Meeting | F3: Aislamientos Y Forros Industriales | H3: 46077 | I3: Se platicó con la empresa, se dedican principalmente para aislantes en proyectos para las empresas, si venden de forma recurrente pero no cumple con el mínimo, los que cumplen llegan a ser proyectos, no les agradó la idea de que se tiene que otorgar un token, lo que comentan es que son muy cerrados y que solo la administradora tiene acceso al token, por lo que factoraje no lo ven viable, de arrendamiento sería por vehículos, compran entre 4 o 5 carros al año para los vendedores | J3: =IF(G3="",F3,G3) -> Aislamientos Y Forros Industriales | K3: =IFERROR(VLOOKUP(Table1[[#This Row],[Top Parent]],'1.- Citas sin this week'!G:G,1,0),"New New") -> New New | L3: =_xlfn.XLOOKUP(Table1[[#This Row],[Top Parent]],Table3[Top Parent],Table3[Date]) -> #N/A | M3: =Table1[[#This Row],[Date]]-Table1[[#This Row],[Last Date]] -> #N/A | N3: =_xlfn.XLOOKUP(Table1[[#This Row],[Top Parent]],Table3[Top Parent],Table3[Owner Name]) -> #N/A | P3: Prospect | Q3: =IF(Table1[[#This Row],[Last Owner]]=Table1[[#This Row],[Owner Name]],"No","Si") -> #N/A | R3: =IF(Table1[[#This Row],[Diferencia de dias]]>182,"Si","No") -> #N/A | S3: Fernanda Rangel | T3: =IF(Table1[[#This Row],[Owner de la cuenta]]=Table1[[#This Row],[Owner Name]],"Si","No") -> Si | U3: Nuevo León | V3: SFAC0006027147 | X3: Industrial Products & Services
C4: =VLOOKUP(D4,Diccionario!A:B,2,0) -> México 1 | D4: Kenia Martinez | E4: Email | F4: Centro Médico De Toluca | H4: 46080 | I4: Eduardo, Ana, me gustaría proponerles una reunión para presentarme formalmente y dar continuidad a la operación del año pasado, en la que aprobamos una línea de arrendamiento por 60 MDP para equipo médico y en la cual actualmente cuentan con una disponibilidad aproximada de 37,162,100.31 MDP para nuevas operaciones. ¿Cómo están de agenda el próximo jueves para reunirnos? | J4: =IF(G4="",F4,G4) -> Centro Médico De Toluca | K4: =IFERROR(VLOOKUP(Table1[[#This Row],[Top Parent]],'1.- Citas sin this week'!G:G,1,0),"New New") -> Centro Médico De Toluca | L4: =_xlfn.XLOOKUP(Table1[[#This Row],[Top Parent]],Table3[Top Parent],Table3[Date]) -> 46072 | M4: =Table1[[#This Row],[Date]]-Table1[[#This Row],[Last Date]] -> 8 | N4: =_xlfn.XLOOKUP(Table1[[#This Row],[Top Parent]],Table3[Top Parent],Table3[Owner Name]) -> Kenia Martinez | P4: Active | Q4: =IF(Table1[[#This Row],[Last Owner]]=Table1[[#This Row],[Owner Name]],"No","Si") -> No | R4: =IF(Table1[[#This Row],[Diferencia de dias]]>182,"Si","No") -> No | S4: Kenia Martinez | T4: =IF(Table1[[#This Row],[Owner de la cuenta]]=Table1[[#This Row],[Owner Name]],"Si","No") -> Si | U4: Estado de México | V4: SFAC0005706024 | W4: 18920958 | X4: Healthcare
C5: =VLOOKUP(D5,Diccionario!A:B,2,0) -> México 1 | D5: Kenia Martinez | E5: Meeting | F5: Orbia Advance Corporation | H5: 46080 | I5: Video C. Equipo NORMET. Dia: Martes 24 7pm. Revisamos temas de facturación, CAL tiempos estimados de firmas y pagos. Ya emitieron pre factura. | J5: =IF(G5="",F5,G5) -> Orbia Advance Corporation | K5: =IFERROR(VLOOKUP(Table1[[#This Row],[Top Parent]],'1.- Citas sin this week'!G:G,1,0),"New New") -> New New | L5: =_xlfn.XLOOKUP(Table1[[#This Row],[Top Parent]],Table3[Top Parent],Table3[Date]) -> #N/A | M5: =Table1[[#This Row],[Date]]-Table1[[#This Row],[Last Date]] -> #N/A | N5: =_xlfn.XLOOKUP(Table1[[#This Row],[Top Parent]],Table3[Top Parent],Table3[Owner Name]) -> #N/A | P5: Prospect | Q5: =IF(Table1[[#This Row],[Last Owner]]=Table1[[#This Row],[Owner Name]],"No","Si") -> #N/A | R5: =IF(Table1[[#This Row],[Diferencia de dias]]>182,"Si","No") -> #N/A | S5: Areli Canche | T5: =IF(Table1[[#This Row],[Owner de la cuenta]]=Table1[[#This Row],[Owner Name]],"Si","No") -> No | U5: Ciudad de México | V5: SFAC0006110706 | X5: Metals, Mining & Metals Fabrication
C6: =VLOOKUP(D6,Diccionario!A:B,2,0) -> Guadalajara | D6: Miguel Ortiz | E6: Meeting | F6: Trabba Prefabricados Concretos | H6: 46080 | I6: Requerimiento: Se agendo cita con Gaby Moreno, Gerente de finanzas de la empresa Trabba Prefabricados Concretos, Buscan una linea de crédito de 1 mdp, Giro: Productos prefabricados de concreto, operan desde hace 20 años, en 2025 vendieron 160 mdp, buen buro de crédito, no trabaja con gobierno, la empresa esta en Zapopan Jalisco, pagina de internet: https:trabba.com.mx | J6: =IF(G6="",F6,G6) -> Trabba Prefabricados Concretos | K6: =IFERROR(VLOOKUP(Table1[[#This Row],[Top Parent]],'1.- Citas sin this week'!G:G,1,0),"New New") -> Trabba Prefabricados Concretos | L6: =_xlfn.XLOOKUP(Table1[[#This Row],[Top Parent]],Table3[Top Parent],Table3[Date]) -> 45923 | M6: =Table1[[#This Row],[Date]]-Table1[[#This Row],[Last Date]] -> 157 | N6: =_xlfn.XLOOKUP(Table1[[#This Row],[Top Parent]],Table3[Top Parent],Table3[Owner Name]) -> Miguel Ortiz | P6: Prospect | Q6: =IF(Table1[[#This Row],[Last Owner]]=Table1[[#This Row],[Owner Name]],"No","Si") -> No | R6: =IF(Table1[[#This Row],[Diferencia de dias]]>182,"Si","No") -> No | S6: Miguel Ortiz | T6: =IF(Table1[[#This Row],[Owner de la cuenta]]=Table1[[#This Row],[Owner Name]],"Si","No") -> Si | U6: Jalisco | V6: SFAC0006103382 | X6: Construction
C7: =VLOOKUP(D7,Diccionario!A:B,2,0) -> México 1 | D7: Patricia Jurado | E7: Reunión de Seguimiento | F7: Natura | H7: 46080 | I7: Presentación de Porpuesta Se presento propuesta, cliente me pide agregar algunos datos adicionales y se acuerda hablar una propuesta más por una línea más grande que cubra los proyectos que vienen en 2026, así como realizarles un ejercicio de eficiencia en los dos escenarios. Se acuerda presentar siguiente semana. Hola Carlos, Antes que nada, muchas gracias por la llamada y el espacio que nos diste el día de hoy. Considero que avanzamos de manera muy positiva y logramos aterrizar varios puntos clave que integraré en la propuesta final. Para poder completarla, ¿me podrías apoyar por favor con el monto total estimado de los proyectos 2026 que podrían entrar dentro del esquema de financiamiento? Esto me permitirá incorporar ese onto total en los ejercicios de eficiencia que estaré preparando. Si pudieras compartirme ese dato el día de hoy, me ayudaría mucho para tenerte toda la información lista el lunes por la tarde. Te agradezco de antemano el apoyo, Saludos | J7: =IF(G7="",F7,G7) -> Natura | K7: =IFERROR(VLOOKUP(Table1[[#This Row],[Top Parent]],'1.- Citas sin this week'!G:G,1,0),"New New") -> Natura | L7: =_xlfn.XLOOKUP(Table1[[#This Row],[Top Parent]],Table3[Top Parent],Table3[Date]) -> 46050 | M7: =Table1[[#This Row],[Date]]-Table1[[#This Row],[Last Date]] -> 30 | N7: =_xlfn.XLOOKUP(Table1[[#This Row],[Top Parent]],Table3[Top Parent],Table3[Owner Name]) -> Patricia Jurado | P7: Active | Q7: =IF(Table1[[#This Row],[Last Owner]]=Table1[[#This Row],[Owner Name]],"No","Si") -> No | R7: =IF(Table1[[#This Row],[Diferencia de dias]]>182,"Si","No") -> No | S7: Patricia Jurado | T7: =IF(Table1[[#This Row],[Owner de la cuenta]]=Table1[[#This Row],[Owner Name]],"Si","No") -> Si | U7: Ciudad de México | V7: 1-52PEUP | X7: Chemicals & Plastics
C8: =VLOOKUP(D8,Diccionario!A:B,2,0) -> LMM 5 | D8: Monserrat Villanueva | E8: Meeting | F8: Impocarnes | G8: Atelier Post CO | H8: 46080 | I8: Junta con dueños, opp inmediata de 20mdp para equipar planta en Ecatepec, posible loan para nueva planta. | J8: =IF(G8="",F8,G8) -> Atelier Post CO | K8: =IFERROR(VLOOKUP(Table1[[#This Row],[Top Parent]],'1.- Citas sin this week'!G:G,1,0),"New New") -> Atelier Post CO | L8: =_xlfn.XLOOKUP(Table1[[#This Row],[Top Parent]],Table3[Top Parent],Table3[Date]) -> 45912 | M8: =Table1[[#This Row],[Date]]-Table1[[#This Row],[Last Date]] -> 168 | N8: =_xlfn.XLOOKUP(Table1[[#This Row],[Top Parent]],Table3[Top Parent],Table3[Owner Name]) -> Monserrat Villanueva | P8: Prospect | Q8: =IF(Table1[[#This Row],[Last Owner]]=Table1[[#This Row],[Owner Name]],"No","Si") -> No | R8: =IF(Table1[[#This Row],[Diferencia de dias]]>182,"Si","No") -> No | S8: Monserrat Villanueva | T8: =IF(Table1[[#This Row],[Owner de la cuenta]]=Table1[[#This Row],[Owner Name]],"Si","No") -> Si | U8: Ciudad de México | V8: SFAC0006087378 | X8: Food Bev & Ag
C9: =VLOOKUP(D9,Diccionario!A:B,2,0) -> LMM 3 | D9: Braulio Martinez | E9: Meeting | F9: Soluciones Logísticas DH | G9: Logistica Interncional De Mercancias | H9: 46080 | I9: Desayuno con Intermerk para conocer a Octavio, platicar sobre proyectos futuros. | J9: =IF(G9="",F9,G9) -> Logistica Interncional De Mercancias | K9: =IFERROR(VLOOKUP(Table1[[#This Row],[Top Parent]],'1.- Citas sin this week'!G:G,1,0),"New New") -> Logistica Interncional De Mercancias | L9: =_xlfn.XLOOKUP(Table1[[#This Row],[Top Parent]],Table3[Top Parent],Table3[Date]) -> 46014 | M9: =Table1[[#This Row],[Date]]-Table1[[#This Row],[Last Date]] -> 66 | N9: =_xlfn.XLOOKUP(Table1[[#This Row],[Top Parent]],Table3[Top Parent],Table3[Owner Name]) -> Braulio Martinez | P9: Active | Q9: =IF(Table1[[#This Row],[Last Owner]]=Table1[[#This Row],[Owner Name]],"No","Si") -> No | R9: =IF(Table1[[#This Row],[Diferencia de dias]]>182,"Si","No") -> No | S9: Braulio Martinez | T9: =IF(Table1[[#This Row],[Owner de la cuenta]]=Table1[[#This Row],[Owner Name]],"Si","No") -> Si | U9: Estado de México | V9: SFAC0006110023 | W9: 6089998.8 | X9: Transportation
C10: =VLOOKUP(D10,Diccionario!A:B,2,0) -> México 2 | D10: David Shaw | E10: Meeting | F10: Vimar Construcciones | H10: 46080 | I10: Reunión con CFO, se platico sobre las oportunidades de plataformas y todo terrenos zoomlion, se buscara avanzar con las propuestas para estar en la línea con condiciones competitivas. | J10: =IF(G10="",F10,G10) -> Vimar Construcciones | K10: =IFERROR(VLOOKUP(Table1[[#This Row],[Top Parent]],'1.- Citas sin this week'!G:G,1,0),"New New") -> Vimar Construcciones | L10: =_xlfn.XLOOKUP(Table1[[#This Row],[Top Parent]],Table3[Top Parent],Table3[Date]) -> 46048 | M10: =Table1[[#This Row],[Date]]-Table1[[#This Row],[Last Date]] -> 32 | N10: =_xlfn.XLOOKUP(Table1[[#This Row],[Top Parent]],Table3[Top Parent],Table3[Owner Name]) -> David Shaw | P10: Prospect | Q10: =IF(Table1[[#This Row],[Last Owner]]=Table1[[#This Row],[Owner Name]],"No","Si") -> No | R10: =IF(Table1[[#This Row],[Diferencia de dias]]>182,"Si","No") -> No | S10: David Shaw | T10: =IF(Table1[[#This Row],[Owner de la cuenta]]=Table1[[#This Row],[Owner Name]],"Si","No") -> Si | U10: Ciudad de México | V10: SFAC0006096575 | X10: Construction
C11: =VLOOKUP(D11,Diccionario!A:B,2,0) -> Estructurados Core | D11: Josue Olvera | E11: Meeting | F11: AVICOLA ABE | H11: 46080 | I11: Reunión con cliente de seguimiento, indica que continúa en cotización de las granjas con distintos proveedores. Se contempla terminar expediente para el martes. | J11: =IF(G11="",F11,G11) -> AVICOLA ABE | K11: =IFERROR(VLOOKUP(Table1[[#This Row],[Top Parent]],'1.- Citas sin this week'!G:G,1,0),"New New") -> AVICOLA ABE | L11: =_xlfn.XLOOKUP(Table1[[#This Row],[Top Parent]],Table3[Top Parent],Table3[Date]) -> 46034 | M11: =Table1[[#This Row],[Date]]-Table1[[#This Row],[Last Date]] -> 46 | N11: =_xlfn.XLOOKUP(Table1[[#This Row],[Top Parent]],Table3[Top Parent],Table3[Owner Name]) -> Josue Olvera | P11: Prospect | Q11: =IF(Table1[[#This Row],[Last Owner]]=Table1[[#This Row],[Owner Name]],"No","Si") -> No | R11: =IF(Table1[[#This Row],[Diferencia de dias]]>182,"Si","No") -> No | S11: Josue Olvera | T11: =IF(Table1[[#This Row],[Owner de la cuenta]]=Table1[[#This Row],[Owner Name]],"Si","No") -> Si | U11: Sinaloa | V11: SFAC0006075787 | X11: Food Bev & Ag
C12: =VLOOKUP(D12,Diccionario!A:B,2,0) -> LMM 1 | D12: Roberto Anaya | E12: Meeting | F12: Representaciones Cyecsa | H12: 46080 | I12: Se reviso propuesta y comparación en base a un crédito simple, el prospecto quedo de revisar la información con su fiscalista y regresar con nosotros. | J12: =IF(G12="",F12,G12) -> Representaciones Cyecsa | K12: =IFERROR(VLOOKUP(Table1[[#This Row],[Top Parent]],'1.- Citas sin this week'!G:G,1,0),"New New") -> Representaciones Cyecsa | L12: =_xlfn.XLOOKUP(Table1[[#This Row],[Top Parent]],Table3[Top Parent],Table3[Date]) -> 46036 | M12: =Table1[[#This Row],[Date]]-Table1[[#This Row],[Last Date]] -> 44 | N12: =_xlfn.XLOOKUP(Table1[[#This Row],[Top Parent]],Table3[Top Parent],Table3[Owner Name]) -> Roberto Anaya | P12: Prospect | Q12: =IF(Table1[[#This Row],[Last Owner]]=Table1[[#This Row],[Owner Name]],"No","Si") -> No | R12: =IF(Table1[[#This Row],[Diferencia de dias]]>182,"Si","No") -> No | S12: Roberto Anaya | T12: =IF(Table1[[#This Row],[Owner de la cuenta]]=Table1[[#This Row],[Owner Name]],"Si","No") -> Si | U12: Jalisco | V12: 1-4WNQ-53 | X12: Forest Products
C13: =VLOOKUP(D13,Diccionario!A:B,2,0) -> Monterrey | D13: Edgar Rodriguez | E13: Meeting | F13: CORPORATIVO DE ACERO Y SERVICIOS ASOCIADOS | H13: 46080 | I13: Visita con el director general de la empresa, dentro del grupo empresarial son 3 razones sociales pero todas venden por debajo de los 30mdp, tienen necesidades de líneas de crédito para factoraje por un monto aproximado de 1mdp. Por las ventas de la empresa y montos de línea es un segmento que no podemos cubrir | J13: =IF(G13="",F13,G13) -> CORPORATIVO DE ACERO Y SERVICIOS ASOCIADOS | K13: =IFERROR(VLOOKUP(Table1[[#This Row],[Top Parent]],'1.- Citas sin this week'!G:G,1,0),"New New") -> New New | L13: =_xlfn.XLOOKUP(Table1[[#This Row],[Top Parent]],Table3[Top Parent],Table3[Date]) -> #N/A | M13: =Table1[[#This Row],[Date]]-Table1[[#This Row],[Last Date]] -> #N/A | N13: =_xlfn.XLOOKUP(Table1[[#This Row],[Top Parent]],Table3[Top Parent],Table3[Owner Name]) -> #N/A | P13: Prospect | Q13: =IF(Table1[[#This Row],[Last Owner]]=Table1[[#This Row],[Owner Name]],"No","Si") -> #N/A | R13: =IF(Table1[[#This Row],[Diferencia de dias]]>182,"Si","No") -> #N/A | S13: Areli Canche | T13: =IF(Table1[[#This Row],[Owner de la cuenta]]=Table1[[#This Row],[Owner Name]],"Si","No") -> No | U13: Chihuahua | V13: SFAC0006058916 | X13: Construction
C14: =VLOOKUP(D14,Diccionario!A:B,2,0) -> Estructurados Core | D14: Josue Olvera | E14: Meeting | F14: ARTEGO | H14: 46076 | I14: Se sostuvo reunión con Felipe Arteaga, empresario con trayectoria de 35 años operando en empresa familiar Frigorizados la Huerta. Se independizó del negocio y decidió operar nuevas línes de negocio. entre ellos, Lácteos Ticoy que fabricó paletas a nivel industrial y empresa que actualmente ya no opera, ARTEGO, que comercializa productos dle extranjero en México, y PAZO GLOBAL, empresa en EEUU que comercializa productos mexicanos en el extranjero. La operación original de paletas cerró debido a temas regulatorios relacionados con permisos de Cofepris, lo que llevó a Felipe a desarrollar un nuevo modelo enfocado en comercialización e importación. Actualmente opera principalmente a través de ARTEGO Logística, empresa con 7 años de facturación bajo un esquema de trading y distribución. El modelo consiste en comprar producto nacional e internacional, importar vía Manzanillo (actualmente con cuatro contenedores en puerto), almacenar y etiquetar mediante terceros, y distribuir a cadenas nacionales. Comercializan productos en las principales cadenas de autoservicio como Walmart (incluyendo Sam?s) y Soriana. Todo el componente operativo es tercerizado, incluyendo fletes, almacenaje y etiquetado, lo que reduce CAPEX pero incrementa la dependencia de flujo constante. El negocio es intensivo en capital de trabajo y funciona bajo un modelo de rotación. Facturaron aproximadamente 160 millones de pesos en el ejercicio anterior y proyectan cerrar el año en 280 millones de pesos, lo que representa un crecimiento cercano al 75%. La facturación se realiza en pesos y la mayoría de las compras son en USD. Sin embargo, cuando detectan volatilidad en el mercado, implementan coberturas cambiarias para proteger márgenes. En cuanto a financiamiento, utilizan factoraje con las cadenas, particularmente con Walmart y Sam?s, así como con Soriana, quien anticipa hasta el 80% del valor de la factura. Señalan que el costo financiero con Walmart es elevado. Los plazos de pago son de aproximadamente 45 días para productos refrigerados y 60 días para productos secos, lo que presiona el ciclo de conversión de efectivo. También mantienen línea de crédito con Fincargo para soporte operativo. El negocio depende estructuralmente del financiamiento para sostener crecimiento, especialmente considerando el volumen de importaciones y la necesidad de mantener inventario disponible. Adicionalmente, cuentan con Pazo Global como vehículo estratégico para representar marcas mexicanas en otros países y traer productos internacionales para su comercialización en México. La intención es escalar a una dimensión mayor mediante esta plataforma, lo que implicará mayor requerimiento de capital de trabajo y posiblemente financiamiento estructurado para expansión. Se identifica que la principal necesidad está en la optimización de capital de trabajo y en la reducción del costo financiero actual. Existe oportunidad de estructurar factoraje que mejoren su operatividad. El modelo no es intensivo en activos fijos, sino en flujo y financiamiento. Próximo paso será solicitar información financiera firmarse en Davincci, información preliminar, así como llamada con el área de factoraje para la oportunidad detectada. | J14: =IF(G14="",F14,G14) -> ARTEGO | K14: =IFERROR(VLOOKUP(Table1[[#This Row],[Top Parent]],'1.- Citas sin this week'!G:G,1,0),"New New") -> New New | L14: =_xlfn.XLOOKUP(Table1[[#This Row],[Top Parent]],Table3[Top Parent],Table3[Date]) -> #N/A | M14: =Table1[[#This Row],[Date]]-Table1[[#This Row],[Last Date]] -> #N/A | N14: =_xlfn.XLOOKUP(Table1[[#This Row],[Top Parent]],Table3[Top Parent],Table3[Owner Name]) -> #N/A | P14: Prospect | Q14: =IF(Table1[[#This Row],[Last Owner]]=Table1[[#This Row],[Owner Name]],"No","Si") -> #N/A | R14: =IF(Table1[[#This Row],[Diferencia de dias]]>182,"Si","No") -> #N/A | S14: Josue Olvera | T14: =IF(Table1[[#This Row],[Owner de la cuenta]]=Table1[[#This Row],[Owner Name]],"Si","No") -> Si | U14: Aguascalientes | V14: SFAC0006103702 | X14: Retail
C15: =VLOOKUP(D15,Diccionario!A:B,2,0) -> México 1 | D15: Armando Estrada | E15: Reunión de Seguimiento | F15: Ubictum | G15: Nadro | H15: 46080 | I15: Reunión para presentar ejercicio MXN 140m. | J15: =IF(G15="",F15,G15) -> Nadro | K15: =IFERROR(VLOOKUP(Table1[[#This Row],[Top Parent]],'1.- Citas sin this week'!G:G,1,0),"New New") -> Nadro | L15: =_xlfn.XLOOKUP(Table1[[#This Row],[Top Parent]],Table3[Top Parent],Table3[Date]) -> 46070 | M15: =Table1[[#This Row],[Date]]-Table1[[#This Row],[Last Date]] -> 10 | N15: =_xlfn.XLOOKUP(Table1[[#This Row],[Top Parent]],Table3[Top Parent],Table3[Owner Name]) -> Armando Estrada | P15: Lost | Q15: =IF(Table1[[#This Row],[Last Owner]]=Table1[[#This Row],[Owner Name]],"No","Si") -> No | R15: =IF(Table1[[#This Row],[Diferencia de dias]]>182,"Si","No") -> No | S15: Armando Estrada | T15: =IF(Table1[[#This Row],[Owner de la cuenta]]=Table1[[#This Row],[Owner Name]],"Si","No") -> Si | U15: Ciudad de México | V15: SFAC0006006404 | W15: 0 | X15: Transportation
C16: =VLOOKUP(D16,Diccionario!A:B,2,0) -> LMM 3 | D16: Braulio Martinez | E16: Meeting | F16: GRUPO ALIANZA-JT | G16: JC MOLDS | H16: 46080 | I16: Firma de contrato de arrendamiento | J16: =IF(G16="",F16,G16) -> JC MOLDS | K16: =IFERROR(VLOOKUP(Table1[[#This Row],[Top Parent]],'1.- Citas sin this week'!G:G,1,0),"New New") -> JC MOLDS | L16: =_xlfn.XLOOKUP(Table1[[#This Row],[Top Parent]],Table3[Top Parent],Table3[Date]) -> 46056 | M16: =Table1[[#This Row],[Date]]-Table1[[#This Row],[Last Date]] -> 24 | N16: =_xlfn.XLOOKUP(Table1[[#This Row],[Top Parent]],Table3[Top Parent],Table3[Owner Name]) -> Braulio Martinez | P16: Dormant | Q16: =IF(Table1[[#This Row],[Last Owner]]=Table1[[#This Row],[Owner Name]],"No","Si") -> No | R16: =IF(Table1[[#This Row],[Diferencia de dias]]>182,"Si","No") -> No | S16: Braulio Martinez | T16: =IF(Table1[[#This Row],[Owner de la cuenta]]=Table1[[#This Row],[Owner Name]],"Si","No") -> Si | U16: Puebla | V16: SFAC0006083885 | W16: 3117751 | X16: Industrial Products & Services
C17: =VLOOKUP(D17,Diccionario!A:B,2,0) -> LMM 5 | D17: Monserrat Villanueva | E17: Meeting | F17: Impocarnes | G17: Atelier Post CO | H17: 46080 | I17: Agenda cita | J17: =IF(G17="",F17,G17) -> Atelier Post CO | K17: =IFERROR(VLOOKUP(Table1[[#This Row],[Top Parent]],'1.- Citas sin this week'!G:G,1,0),"New New") -> Atelier Post CO | L17: =_xlfn.XLOOKUP(Table1[[#This Row],[Top Parent]],Table3[Top Parent],Table3[Date]) -> 45912 | M17: =Table1[[#This Row],[Date]]-Table1[[#This Row],[Last Date]] -> 168 | N17: =_xlfn.XLOOKUP(Table1[[#This Row],[Top Parent]],Table3[Top Parent],Table3[Owner Name]) -> Monserrat Villanueva | P17: Prospect | Q17: =IF(Table1[[#This Row],[Last Owner]]=Table1[[#This Row],[Owner Name]],"No","Si") -> No | R17: =IF(Table1[[#This Row],[Diferencia de dias]]>182,"Si","No") -> No | S17: Monserrat Villanueva | T17: =IF(Table1[[#This Row],[Owner de la cuenta]]=Table1[[#This Row],[Owner Name]],"Si","No") -> Si | U17: Ciudad de México | V17: SFAC0006087378 | X17: Food Bev & Ag
C18: =VLOOKUP(D18,Diccionario!A:B,2,0) -> México 1 | D18: Kenia Martinez | E18: Meeting | F18: Mexichem | H18: 46080 | I18: Video C. 8 am Asistentes Abi Carreon y Kenia M. Revisamos cronograma de entregas, variacion en precios del equipo NORMET, y platicamos sobre el equipo de Voz y Datos de EPIROC, la confirguracion inicial cambio y hay afectaciones en tiempos de entrega, y costos. Tambien platicamos sobre el proceso del contrato, me pide que se envie hoy a mas tardar, para que logremos entrar al proceso de validacion interna. | J18: =IF(G18="",F18,G18) -> Mexichem | K18: =IFERROR(VLOOKUP(Table1[[#This Row],[Top Parent]],'1.- Citas sin this week'!G:G,1,0),"New New") -> Mexichem | L18: =_xlfn.XLOOKUP(Table1[[#This Row],[Top Parent]],Table3[Top Parent],Table3[Date]) -> 46070 | M18: =Table1[[#This Row],[Date]]-Table1[[#This Row],[Last Date]] -> 10 | N18: =_xlfn.XLOOKUP(Table1[[#This Row],[Top Parent]],Table3[Top Parent],Table3[Owner Name]) -> Kenia Martinez | P18: Lost | Q18: =IF(Table1[[#This Row],[Last Owner]]=Table1[[#This Row],[Owner Name]],"No","Si") -> No | R18: =IF(Table1[[#This Row],[Diferencia de dias]]>182,"Si","No") -> No | S18: Kenia Martinez | T18: =IF(Table1[[#This Row],[Owner de la cuenta]]=Table1[[#This Row],[Owner Name]],"Si","No") -> Si | U18: Ciudad de México | V18: 1-3HYG-425 | W18: 0 | X18: Chemicals & Plastics
C19: =VLOOKUP(D19,Diccionario!A:B,2,0) -> Estructurados Core | D19: Josue Olvera | E19: Meeting | F19: SALZILLO | H19: 46079 | I19: se tiene contacto con Antonio empresa dedicada al sector de transoprte contando con flotilla de camiones opera desde el 2007 facturacion mayor a 100 mdp, refiere buen buro no trabajar con gobierno requiere esquemas de arrendamiento | J19: =IF(G19="",F19,G19) -> SALZILLO | K19: =IFERROR(VLOOKUP(Table1[[#This Row],[Top Parent]],'1.- Citas sin this week'!G:G,1,0),"New New") -> SALZILLO | L19: =_xlfn.XLOOKUP(Table1[[#This Row],[Top Parent]],Table3[Top Parent],Table3[Date]) -> 45786 | M19: =Table1[[#This Row],[Date]]-Table1[[#This Row],[Last Date]] -> 293 | N19: =_xlfn.XLOOKUP(Table1[[#This Row],[Top Parent]],Table3[Top Parent],Table3[Owner Name]) -> Josue Olvera | P19: Prospect | Q19: =IF(Table1[[#This Row],[Last Owner]]=Table1[[#This Row],[Owner Name]],"No","Si") -> No | R19: =IF(Table1[[#This Row],[Diferencia de dias]]>182,"Si","No") -> Si | S19: Josue Olvera | T19: =IF(Table1[[#This Row],[Owner de la cuenta]]=Table1[[#This Row],[Owner Name]],"Si","No") -> Si | U19: Guanajuato | V19: SFAC0006075981 | X19: Transportation
C20: =VLOOKUP(D20,Diccionario!A:B,2,0) -> Estructurados Core | D20: Manuel Ibal | E20: Meeting | F20: Aguacates Terravo | H20: 46078 | I20: Cita con Ángel Navarro Director General y Gabriela CFO, tienen la necesidad de compra de equipo para el empaque, transporte, y en un mediano plazo liquidar socios. Ventas: $250MDP. Inversiones se han realizado con inversionistas. Clientes: Distribuidores. Mercados de abastos. Exportación directas. Pains: Poca liquidez y requerimientos de capital de trabajo. Los activos están en un fideicomiso de garantía diseñado para solicitar crédito. Bancos: Bajío. Revolventes. LEMs. Con pagos semestrales. Acitvos sujetos a fin: lineas de empaque. | J20: =IF(G20="",F20,G20) -> Aguacates Terravo | K20: =IFERROR(VLOOKUP(Table1[[#This Row],[Top Parent]],'1.- Citas sin this week'!G:G,1,0),"New New") -> New New | L20: =_xlfn.XLOOKUP(Table1[[#This Row],[Top Parent]],Table3[Top Parent],Table3[Date]) -> #N/A | M20: =Table1[[#This Row],[Date]]-Table1[[#This Row],[Last Date]] -> #N/A | N20: =_xlfn.XLOOKUP(Table1[[#This Row],[Top Parent]],Table3[Top Parent],Table3[Owner Name]) -> #N/A | Q20: =IF(Table1[[#This Row],[Last Owner]]=Table1[[#This Row],[Owner Name]],"No","Si") -> #N/A | R20: =IF(Table1[[#This Row],[Diferencia de dias]]>182,"Si","No") -> #N/A | S20: Manuel Ibal | T20: =IF(Table1[[#This Row],[Owner de la cuenta]]=Table1[[#This Row],[Owner Name]],"Si","No") -> Si | U20: Jalisco | V20: SFAC0006110888 | X20: Food Bev & Ag
C21: =VLOOKUP(D21,Diccionario!A:B,2,0) -> Estructurados Core | D21: Manuel Ibal | E21: Meeting | F21: BANANAS SAN JORGE | H21: 46078 | I21: Reunión con el CFO de la empresa Miguel Ángel, la empresa pertenece a un Grupo empresarial llamado Grupo San Jorge, se dedican a la producción de banana, limón, coco y papaya, tienen una empresa de plasticos que son los que fabrican las cajas para consumo propio y vender a terceros, tienen la necesidad de comprar equipos pero para la nave industrial que tienen en Mc Allen TX. San Jorge: Usa lineas revolvente, bajio, santander bbv. Con revolvencia para comprar de oportunidad. No se preguntaron montos. SI GARANTIA HIPOTECARIA. No se pudo recabar mayor información. Se agendó cita el miércoles para estar con el dueño. | J21: =IF(G21="",F21,G21) -> BANANAS SAN JORGE | K21: =IFERROR(VLOOKUP(Table1[[#This Row],[Top Parent]],'1.- Citas sin this week'!G:G,1,0),"New New") -> New New | L21: =_xlfn.XLOOKUP(Table1[[#This Row],[Top Parent]],Table3[Top Parent],Table3[Date]) -> #N/A | M21: =Table1[[#This Row],[Date]]-Table1[[#This Row],[Last Date]] -> #N/A | N21: =_xlfn.XLOOKUP(Table1[[#This Row],[Top Parent]],Table3[Top Parent],Table3[Owner Name]) -> #N/A | P21: Prospect | Q21: =IF(Table1[[#This Row],[Last Owner]]=Table1[[#This Row],[Owner Name]],"No","Si") -> #N/A | R21: =IF(Table1[[#This Row],[Diferencia de dias]]>182,"Si","No") -> #N/A | S21: Manuel Ibal | T21: =IF(Table1[[#This Row],[Owner de la cuenta]]=Table1[[#This Row],[Owner Name]],"Si","No") -> Si | U21: Jalisco | V21: SFAC0006072621 | X21: Food Bev & Ag
C22: =VLOOKUP(D22,Diccionario!A:B,2,0) -> LMM 3 | D22: Vadir Peña | E22: Meeting | F22: Dmtress | H22: 46079 | I22: Nos reunimos con la Lic. Esmeralda Pereyra, quien nos indicó que durante el presente ejercicio tienen planeado dar salida a un camión, mismo que debe de ser renovado, buscaremos reunión la siguiente semana con el Lic. Víctor Marquinez. | J22: =IF(G22="",F22,G22) -> Dmtress | K22: New New | L22: =_xlfn.XLOOKUP(Table1[[#This Row],[Top Parent]],Table3[Top Parent],Table3[Date]) -> 45826 | M22: =Table1[[#This Row],[Date]]-Table1[[#This Row],[Last Date]] -> 253 | N22: =_xlfn.XLOOKUP(Table1[[#This Row],[Top Parent]],Table3[Top Parent],Table3[Owner Name]) -> Diego Aviña | P22: Dormant | Q22: =IF(Table1[[#This Row],[Last Owner]]=Table1[[#This Row],[Owner Name]],"No","Si") -> Si | R22: =IF(Table1[[#This Row],[Diferencia de dias]]>182,"Si","No") -> Si | S22: Vadir Peña | T22: =IF(Table1[[#This Row],[Owner de la cuenta]]=Table1[[#This Row],[Owner Name]],"Si","No") -> Si | U22: Veracruz | V22: SFAC0006059948 | W22: 224302.1 | X22: Chemicals & Plastics
C23: =VLOOKUP(D23,Diccionario!A:B,2,0) -> Guadalajara | D23: Dulce Villegas | E23: Meeting | F23: Hospital San Javier | H23: 46079 | I23: Visita en las oficinas del cliente para dialogar respecto a la línea calificada para el equipo del robot quirúrgico y revisar la viabilidad de que cierren este proyecto con nosotros. Recientemente firmaron un Loan con BANSI por MXN 27 MM a un plazo de 60 meses más 1 año de gracias, TIIE + 4 puntos. Le haremos llegar un análisis de VPN entre este crédito y nuestra propuesta de arrendamiento. | J23: =IF(G23="",F23,G23) -> Hospital San Javier | K23: =IFERROR(VLOOKUP(Table1[[#This Row],[Top Parent]],'1.- Citas sin this week'!G:G,1,0),"New New") -> Hospital San Javier | L23: =_xlfn.XLOOKUP(Table1[[#This Row],[Top Parent]],Table3[Top Parent],Table3[Date]) -> 45994 | M23: =Table1[[#This Row],[Date]]-Table1[[#This Row],[Last Date]] -> 85 | N23: =_xlfn.XLOOKUP(Table1[[#This Row],[Top Parent]],Table3[Top Parent],Table3[Owner Name]) -> Dulce Villegas | P23: Active | Q23: =IF(Table1[[#This Row],[Last Owner]]=Table1[[#This Row],[Owner Name]],"No","Si") -> No | R23: =IF(Table1[[#This Row],[Diferencia de dias]]>182,"Si","No") -> No | S23: Dulce Villegas | T23: =IF(Table1[[#This Row],[Owner de la cuenta]]=Table1[[#This Row],[Owner Name]],"Si","No") -> Si | U23: Jalisco | V23: SFAC0006005196 | W23: 68316343 | X23: Healthcare
C24: =VLOOKUP(D24,Diccionario!A:B,2,0) -> Guadalajara | D24: Dulce Villegas | E24: Meeting | F24: ZAZ MUEBLES Y ALGO MAS | H24: 46079 | I24: Conferencia con el cliente para revisar oportunidades para este 2026. | J24: =IF(G24="",F24,G24) -> ZAZ MUEBLES Y ALGO MAS | K24: =IFERROR(VLOOKUP(Table1[[#This Row],[Top Parent]],'1.- Citas sin this week'!G:G,1,0),"New New") -> New New | L24: =_xlfn.XLOOKUP(Table1[[#This Row],[Top Parent]],Table3[Top Parent],Table3[Date]) -> #N/A | M24: =Table1[[#This Row],[Date]]-Table1[[#This Row],[Last Date]] -> #N/A | N24: =_xlfn.XLOOKUP(Table1[[#This Row],[Top Parent]],Table3[Top Parent],Table3[Owner Name]) -> #N/A | P24: Prospect | Q24: =IF(Table1[[#This Row],[Last Owner]]=Table1[[#This Row],[Owner Name]],"No","Si") -> #N/A | R24: =IF(Table1[[#This Row],[Diferencia de dias]]>182,"Si","No") -> #N/A | S24: Dulce Villegas | T24: =IF(Table1[[#This Row],[Owner de la cuenta]]=Table1[[#This Row],[Owner Name]],"Si","No") -> Si | U24: Jalisco | V24: SFAC0006021738 | X24: Consumer Products
C25: =VLOOKUP(D25,Diccionario!A:B,2,0) -> Guadalajara | D25: Fernando Carbajal | E25: Meeting | F25: MADOBOX | H25: 46079 | I25: EMPRESA / CIUDAD: New New Madobox / Uruapan, Mich VENTAS: $583 MM CITA CON: Alejandro Macias Doddoli - Dueño ACTIVIDAD: Fabricación de cajas agrícola de cartón corrugado. CLIENTES / PLAZO PAGO: Mission Produce, Calavo, WestPack, Aztecavo, Agrovisión plazo máximo de 30 días. ACTIVOS CORE: Flexo, Cortadora, Corrugadora, Troqueladora. (Financian con el proveedor). PROVEEDORES / PLAZO PAGO: Georgia Pacific, Arizlu, Licbox. BANCOS CORTO PLAZO / MONTOS / % US0: Bajío y BBVA AP y AF de 3 a 7 años con garantía de la maquinaría, no hay corto. Arrendamientos en USD. OPORTUNIDAD: Flexo de $960 M USD en AP de 60 a 84 meses para línea de papaya y plátano, proveedor chino. Cuando mande IF financiera se hará también propuesta para reestructura de pasivos. | J25: =IF(G25="",F25,G25) -> MADOBOX | K25: =IFERROR(VLOOKUP(Table1[[#This Row],[Top Parent]],'1.- Citas sin this week'!G:G,1,0),"New New") -> New New | L25: =_xlfn.XLOOKUP(Table1[[#This Row],[Top Parent]],Table3[Top Parent],Table3[Date]) -> #N/A | M25: =Table1[[#This Row],[Date]]-Table1[[#This Row],[Last Date]] -> #N/A | N25: =_xlfn.XLOOKUP(Table1[[#This Row],[Top Parent]],Table3[Top Parent],Table3[Owner Name]) -> #N/A | P25: Prospect | Q25: =IF(Table1[[#This Row],[Last Owner]]=Table1[[#This Row],[Owner Name]],"No","Si") -> #N/A | R25: =IF(Table1[[#This Row],[Diferencia de dias]]>182,"Si","No") -> #N/A | S25: Fernando Carbajal | T25: =IF(Table1[[#This Row],[Owner de la cuenta]]=Table1[[#This Row],[Owner Name]],"Si","No") -> Si | U25: Michoacán | V25: SFAC0006075570 | X25: Forest Products
C26: =VLOOKUP(D26,Diccionario!A:B,2,0) -> Guadalajara | D26: Marianna Peña | E26: Meeting | F26: Agroservicios Nacionales | H26: 46076 | I26: Por contingencia se movió la reunión de presencial a videollamada, solo pudo estar el tesorero. Tienen necesidad de financiamiento de 1K camionetas para distribución en distintos estados. Podría existir oportunidad de refinanciamiento de líneas de corto plazo, necesario indagar que exista maquinaria suficiente. La visita presencial se pospuso para la siguiente semana para platicar más a detalle con DG. | J26: =IF(G26="",F26,G26) -> Agroservicios Nacionales | K26: =IFERROR(VLOOKUP(Table1[[#This Row],[Top Parent]],'1.- Citas sin this week'!G:G,1,0),"New New") -> New New | L26: =_xlfn.XLOOKUP(Table1[[#This Row],[Top Parent]],Table3[Top Parent],Table3[Date]) -> #N/A | M26: =Table1[[#This Row],[Date]]-Table1[[#This Row],[Last Date]] -> #N/A | N26: =_xlfn.XLOOKUP(Table1[[#This Row],[Top Parent]],Table3[Top Parent],Table3[Owner Name]) -> #N/A | P26: Prospect | Q26: =IF(Table1[[#This Row],[Last Owner]]=Table1[[#This Row],[Owner Name]],"No","Si") -> #N/A | R26: =IF(Table1[[#This Row],[Diferencia de dias]]>182,"Si","No") -> #N/A | S26: Marianna Peña | T26: =IF(Table1[[#This Row],[Owner de la cuenta]]=Table1[[#This Row],[Owner Name]],"Si","No") -> Si | U26: Jalisco | V26: SFAC0005578380 | X26: Chemicals & Plastics
C27: =VLOOKUP(D27,Diccionario!A:B,2,0) -> Guadalajara | D27: Miguel Ortiz | E27: Meeting | F27: FASST | G27: Call Fasst | H27: 46078 | I27: Hora y fecha de cita: Miércoles 23 de febrero 10:00 am Originador: Miguel Ortiz Con quien se habló: Alfonso Vega Puesto: CFO Actividad de la empresa: Desarrollo de sistema de telecomunicación para servicios de cobranza, atención a clientes etc. Ventas de la empresa: $1340 millones Buró de crédito: Ok Sector privado 100% Años de operación: 23 años Ubicación: Querétaro. Busca servicio de Arrendamiento y crédito, prospecto acudió al evento Impulsando Empresas Querétaro. | J27: =IF(G27="",F27,G27) -> Call Fasst | K27: =IFERROR(VLOOKUP(Table1[[#This Row],[Top Parent]],'1.- Citas sin this week'!G:G,1,0),"New New") -> New New | L27: =_xlfn.XLOOKUP(Table1[[#This Row],[Top Parent]],Table3[Top Parent],Table3[Date]) -> #N/A | M27: =Table1[[#This Row],[Date]]-Table1[[#This Row],[Last Date]] -> #N/A | N27: =_xlfn.XLOOKUP(Table1[[#This Row],[Top Parent]],Table3[Top Parent],Table3[Owner Name]) -> #N/A | P27: Prospect | Q27: =IF(Table1[[#This Row],[Last Owner]]=Table1[[#This Row],[Owner Name]],"No","Si") -> #N/A | R27: =IF(Table1[[#This Row],[Diferencia de dias]]>182,"Si","No") -> #N/A | S27: Miguel Ortiz | T27: =IF(Table1[[#This Row],[Owner de la cuenta]]=Table1[[#This Row],[Owner Name]],"Si","No") -> Si | U27: Querétaro | V27: SFAC0006022225 | X27: Technology & Business Services
C28: =VLOOKUP(D28,Diccionario!A:B,2,0) -> LMM 3 | D28: Jose Nava | E28: Meeting | F28: CAJAS Y CORRUGADOS PARA EMPAQUE | H28: 46079 | I28: Firma de contrato | J28: =IF(G28="",F28,G28) -> CAJAS Y CORRUGADOS PARA EMPAQUE | K28: =IFERROR(VLOOKUP(Table1[[#This Row],[Top Parent]],'1.- Citas sin this week'!G:G,1,0),"New New") -> CAJAS Y CORRUGADOS PARA EMPAQUE | L28: =_xlfn.XLOOKUP(Table1[[#This Row],[Top Parent]],Table3[Top Parent],Table3[Date]) -> 46073 | M28: =Table1[[#This Row],[Date]]-Table1[[#This Row],[Last Date]] -> 6 | N28: =_xlfn.XLOOKUP(Table1[[#This Row],[Top Parent]],Table3[Top Parent],Table3[Owner Name]) -> Jose Nava | P28: Dormant | Q28: =IF(Table1[[#This Row],[Last Owner]]=Table1[[#This Row],[Owner Name]],"No","Si") -> No | R28: =IF(Table1[[#This Row],[Diferencia de dias]]>182,"Si","No") -> No | S28: Jose Nava | T28: =IF(Table1[[#This Row],[Owner de la cuenta]]=Table1[[#This Row],[Owner Name]],"Si","No") -> Si | U28: Puebla | V28: SFAC0006039064 | W28: 2752767.5 | X28: Forest Products
C29: =VLOOKUP(D29,Diccionario!A:B,2,0) -> Guadalajara | D29: Natalia Bernat | E29: Meeting | F29: Terminal de Almacenamiento y Distribución de Asfalto | H29: 46079 | I29: Cita con TADA, con HUgo Peña, tienen 30 autos utilitarios y 51 tracto camiones, empresa se dedica a elaboracion y distribución de asfalto. | J29: =IF(G29="",F29,G29) -> Terminal de Almacenamiento y Distribución de Asfalto | K29: =IFERROR(VLOOKUP(Table1[[#This Row],[Top Parent]],'1.- Citas sin this week'!G:G,1,0),"New New") -> New New | L29: =_xlfn.XLOOKUP(Table1[[#This Row],[Top Parent]],Table3[Top Parent],Table3[Date]) -> #N/A | M29: =Table1[[#This Row],[Date]]-Table1[[#This Row],[Last Date]] -> #N/A | N29: =_xlfn.XLOOKUP(Table1[[#This Row],[Top Parent]],Table3[Top Parent],Table3[Owner Name]) -> #N/A | P29: Prospect | Q29: =IF(Table1[[#This Row],[Last Owner]]=Table1[[#This Row],[Owner Name]],"No","Si") -> #N/A | R29: =IF(Table1[[#This Row],[Diferencia de dias]]>182,"Si","No") -> #N/A | S29: Natalia Bernat | T29: =IF(Table1[[#This Row],[Owner de la cuenta]]=Table1[[#This Row],[Owner Name]],"Si","No") -> Si | U29: Guanajuato | V29: SFAC0006024350 | X29: Construction
C30: =VLOOKUP(D30,Diccionario!A:B,2,0) -> México 1 | D30: Kenia Martinez | E30: Meeting | F30: Ecoshell | H30: 46079 | I30: Seguimiento con Oscar para Anexo de Cartera, y estatus de la operación. Me confirmo que ya envio el anexo a Nidi con los datos correctos, le propuse reunirnos la siguiente semana para dar celeridad a la oportunidad. Trabajare en conjunto con Nidi para coordinar esta sesión y avanzar. | J30: =IF(G30="",F30,G30) -> Ecoshell | K30: =IFERROR(VLOOKUP(Table1[[#This Row],[Top Parent]],'1.- Citas sin this week'!G:G,1,0),"New New") -> Ecoshell | L30: =_xlfn.XLOOKUP(Table1[[#This Row],[Top Parent]],Table3[Top Parent],Table3[Date]) -> 46028 | M30: =Table1[[#This Row],[Date]]-Table1[[#This Row],[Last Date]] -> 51 | N30: =_xlfn.XLOOKUP(Table1[[#This Row],[Top Parent]],Table3[Top Parent],Table3[Owner Name]) -> Kenia Martinez | P30: Prospect | Q30: =IF(Table1[[#This Row],[Last Owner]]=Table1[[#This Row],[Owner Name]],"No","Si") -> No | R30: =IF(Table1[[#This Row],[Diferencia de dias]]>182,"Si","No") -> No | S30: Kenia Martinez | T30: =IF(Table1[[#This Row],[Owner de la cuenta]]=Table1[[#This Row],[Owner Name]],"Si","No") -> Si | U30: Ciudad de México | V30: SFAC0006001594 | X30: Chemicals & Plastics
C31: =VLOOKUP(D31,Diccionario!A:B,2,0) -> LMM 4 | D31: Alexandra Ramírez | E31: Meeting | F31: Güntner de México | H31: 46079 | I31: reunion con jesus cruz para revisar requerimiento de cnc | J31: =IF(G31="",F31,G31) -> Güntner de México | K31: =IFERROR(VLOOKUP(Table1[[#This Row],[Top Parent]],'1.- Citas sin this week'!G:G,1,0),"New New") -> Güntner de México | L31: =_xlfn.XLOOKUP(Table1[[#This Row],[Top Parent]],Table3[Top Parent],Table3[Date]) -> 45988 | M31: =Table1[[#This Row],[Date]]-Table1[[#This Row],[Last Date]] -> 91 | N31: =_xlfn.XLOOKUP(Table1[[#This Row],[Top Parent]],Table3[Top Parent],Table3[Owner Name]) -> Alexandra Ramírez | P31: Prospect | Q31: =IF(Table1[[#This Row],[Last Owner]]=Table1[[#This Row],[Owner Name]],"No","Si") -> No | R31: =IF(Table1[[#This Row],[Diferencia de dias]]>182,"Si","No") -> No | S31: Alexandra Ramírez | T31: =IF(Table1[[#This Row],[Owner de la cuenta]]=Table1[[#This Row],[Owner Name]],"Si","No") -> Si | U31: Nuevo León | V31: SFAC0005506431 | X31: Industrial Products & Services
C32: =VLOOKUP(D32,Diccionario!A:B,2,0) -> Monterrey | D32: Sergio Mange | E32: Meeting | F32: Tenedora Agnico Eagle México | H32: 46079 | I32: Reunión con Marco Perea, Gerente General de la mina Pinos Altos (Chihuahua). Se llevó a cabo una videollamada en la que se presentaron los principales puntos de valor agregado que podemos aportar a su operación. Marco comentó que la propuesta es de su interés y planteó realizar una segunda videollamada, ahora incluyendo al Ing. Alberto Díaz, Director de Compras de la mina. En esta siguiente reunión, el Ing. Díaz nos podrá brindar una mayor perspectiva sobre los equipos que tienen previstos para la operación 2026, así como las estructuras de compra y esquemas que actualmente utilizan. | J32: =IF(G32="",F32,G32) -> Tenedora Agnico Eagle México | K32: =IFERROR(VLOOKUP(Table1[[#This Row],[Top Parent]],'1.- Citas sin this week'!G:G,1,0),"New New") -> Tenedora Agnico Eagle México | L32: =_xlfn.XLOOKUP(Table1[[#This Row],[Top Parent]],Table3[Top Parent],Table3[Date]) -> 46065 | M32: =Table1[[#This Row],[Date]]-Table1[[#This Row],[Last Date]] -> 14 | N32: =_xlfn.XLOOKUP(Table1[[#This Row],[Top Parent]],Table3[Top Parent],Table3[Owner Name]) -> Sergio Mange | P32: Prospect | Q32: =IF(Table1[[#This Row],[Last Owner]]=Table1[[#This Row],[Owner Name]],"No","Si") -> No | R32: =IF(Table1[[#This Row],[Diferencia de dias]]>182,"Si","No") -> No | S32: Sergio Mange | T32: =IF(Table1[[#This Row],[Owner de la cuenta]]=Table1[[#This Row],[Owner Name]],"Si","No") -> Si | U32: Chihuahua | V32: SFAC0005644825 | X32: Metals, Mining & Metals Fabrication
C33: =VLOOKUP(D33,Diccionario!A:B,2,0) -> Guadalajara | D33: Omar Rodríguez | E33: Meeting | F33: Empaques y diseños de polietileno | H33: 46079 | I33: Visita a la empresa con Eduardo Covarruvias Director de Finanzas y Lucy Barba de Tesorería. La empresa se dedica al ensamble de cartón corrugado, plástico corrugado, foam de polietileno para empresas como San Mina, Jabil, HP, Flextronic, Nefab, Veritiv, Continental, etc a plazos de 60 días. Este plazo está empatado con sus proveedores y comentaban que tenían buen flujo. Están por realizar una sustitución de activos por al menos 10 mdp (dobladoras, suajadoras, pegadoras, etc). Se comentó la posibilidad de un S&LB pero comentó que no estaban interesados. Trabajan hoy factoraje con RTS pero derivado a que están buscando mejorar condiciones con clientes no quisieran otro proveedor de factoraje. El 85% de sus ventas son en usd y facturan 12 mdd al año. Se da de alta oportunidad. | J33: =IF(G33="",F33,G33) -> Empaques y diseños de polietileno | K33: =IFERROR(VLOOKUP(Table1[[#This Row],[Top Parent]],'1.- Citas sin this week'!G:G,1,0),"New New") -> New New | L33: =_xlfn.XLOOKUP(Table1[[#This Row],[Top Parent]],Table3[Top Parent],Table3[Date]) -> #N/A | M33: =Table1[[#This Row],[Date]]-Table1[[#This Row],[Last Date]] -> #N/A | N33: =_xlfn.XLOOKUP(Table1[[#This Row],[Top Parent]],Table3[Top Parent],Table3[Owner Name]) -> #N/A | P33: Prospect | Q33: =IF(Table1[[#This Row],[Last Owner]]=Table1[[#This Row],[Owner Name]],"No","Si") -> #N/A | R33: =IF(Table1[[#This Row],[Diferencia de dias]]>182,"Si","No") -> #N/A | S33: Omar Rodríguez | T33: =IF(Table1[[#This Row],[Owner de la cuenta]]=Table1[[#This Row],[Owner Name]],"Si","No") -> Si | U33: Jalisco | V33: SFAC0006026438 | X33: Forest Products
C34: =VLOOKUP(D34,Diccionario!A:B,2,0) -> México 1 | D34: Fernando Martin | E34: Seguimiento | F34: Unifoods | H34: 46079 | I34: reunión con Contador de la empresa para aclaración de dudas financieras al cierre 2025. Se acordó el envío de información referente a sus pasivos financieros para poder ingresar a riesgos la operación. Se acordó el día 27 de febrero el tener la información para poder hacer HO el lunes (2) o martes (3) de marzo. | J34: =IF(G34="",F34,G34) -> Unifoods | K34: =IFERROR(VLOOKUP(Table1[[#This Row],[Top Parent]],'1.- Citas sin this week'!G:G,1,0),"New New") -> Unifoods | L34: =_xlfn.XLOOKUP(Table1[[#This Row],[Top Parent]],Table3[Top Parent],Table3[Date]) -> 46030 | M34: =Table1[[#This Row],[Date]]-Table1[[#This Row],[Last Date]] -> 49 | N34: =_xlfn.XLOOKUP(Table1[[#This Row],[Top Parent]],Table3[Top Parent],Table3[Owner Name]) -> Fernando Martin | P34: Prospect | Q34: =IF(Table1[[#This Row],[Last Owner]]=Table1[[#This Row],[Owner Name]],"No","Si") -> No | R34: =IF(Table1[[#This Row],[Diferencia de dias]]>182,"Si","No") -> No | S34: Fernando Martin | T34: =IF(Table1[[#This Row],[Owner de la cuenta]]=Table1[[#This Row],[Owner Name]],"Si","No") -> Si | U34: Ciudad de México | V34: 1-3HZC-775 | X34: Food Bev & Ag
C35: =VLOOKUP(D35,Diccionario!A:B,2,0) -> LMM 1 | D35: Alejandro Monteón | E35: Meeting | F35: Logística Express La Bufa | H35: 46079 | I35: Seguimiento a Factoraje, se le presentó resultados de Sintach | J35: =IF(G35="",F35,G35) -> Logística Express La Bufa | K35: =IFERROR(VLOOKUP(Table1[[#This Row],[Top Parent]],'1.- Citas sin this week'!G:G,1,0),"New New") -> Logística Express La Bufa | L35: =_xlfn.XLOOKUP(Table1[[#This Row],[Top Parent]],Table3[Top Parent],Table3[Date]) -> 46070 | M35: =Table1[[#This Row],[Date]]-Table1[[#This Row],[Last Date]] -> 9 | N35: =_xlfn.XLOOKUP(Table1[[#This Row],[Top Parent]],Table3[Top Parent],Table3[Owner Name]) -> Alejandro Monteón | P35: Dormant | Q35: =IF(Table1[[#This Row],[Last Owner]]=Table1[[#This Row],[Owner Name]],"No","Si") -> No | R35: =IF(Table1[[#This Row],[Diferencia de dias]]>182,"Si","No") -> No | S35: Alejandro Monteón | T35: =IF(Table1[[#This Row],[Owner de la cuenta]]=Table1[[#This Row],[Owner Name]],"Si","No") -> Si | U35: Zacatecas | V35: SFAC0006076081 | W35: 11764701 | X35: Transportation
C36: =VLOOKUP(D36,Diccionario!A:B,2,0) -> LMM 1 | D36: Alejandro Monteón | E36: Meeting | F36: Mova Printing Solutions | H36: 46079 | I36: Visita con director regional para ver nueva opp. | J36: =IF(G36="",F36,G36) -> Mova Printing Solutions | K36: =IFERROR(VLOOKUP(Table1[[#This Row],[Top Parent]],'1.- Citas sin this week'!G:G,1,0),"New New") -> Mova Printing Solutions | L36: =_xlfn.XLOOKUP(Table1[[#This Row],[Top Parent]],Table3[Top Parent],Table3[Date]) -> 45931 | M36: =Table1[[#This Row],[Date]]-Table1[[#This Row],[Last Date]] -> 148 | N36: =_xlfn.XLOOKUP(Table1[[#This Row],[Top Parent]],Table3[Top Parent],Table3[Owner Name]) -> Alejandro Monteón | P36: Active | Q36: =IF(Table1[[#This Row],[Last Owner]]=Table1[[#This Row],[Owner Name]],"No","Si") -> No | R36: =IF(Table1[[#This Row],[Diferencia de dias]]>182,"Si","No") -> No | S36: Alejandro Monteón | T36: =IF(Table1[[#This Row],[Owner de la cuenta]]=Table1[[#This Row],[Owner Name]],"Si","No") -> Si | U36: Jalisco | V36: SFAC0006008587 | W36: 33515745 | X36: Forest Products
C37: =VLOOKUP(D37,Diccionario!A:B,2,0) -> Guadalajara | D37: Samuel Cepeda | E37: Meeting | F37: Ticoy Foods | H37: 46077 | I37: Ticoy Foods - new new: Reunión con Felipe Arteaga, esta reunión quedó pendiente de la gira de Ags, hay oportunidad para equipo de transporte y refrigeración (este en S&LB) venden +250mdp, tienen una empresa hermana holistik dedicada a frutos congelados, nos van a pasar cotizaciones para propuesta. Están interesados en escuchar al equipo de factoraje ya que le venden a Soriana y Waltmart, se busca reunión siguiente semana con ellos y Toño. | J37: =IF(G37="",F37,G37) -> Ticoy Foods | K37: =IFERROR(VLOOKUP(Table1[[#This Row],[Top Parent]],'1.- Citas sin this week'!G:G,1,0),"New New") -> New New | L37: =_xlfn.XLOOKUP(Table1[[#This Row],[Top Parent]],Table3[Top Parent],Table3[Date]) -> #N/A | M37: =Table1[[#This Row],[Date]]-Table1[[#This Row],[Last Date]] -> #N/A | N37: =_xlfn.XLOOKUP(Table1[[#This Row],[Top Parent]],Table3[Top Parent],Table3[Owner Name]) -> #N/A | P37: Prospect | Q37: =IF(Table1[[#This Row],[Last Owner]]=Table1[[#This Row],[Owner Name]],"No","Si") -> #N/A | R37: =IF(Table1[[#This Row],[Diferencia de dias]]>182,"Si","No") -> #N/A | S37: Samuel Cepeda | T37: =IF(Table1[[#This Row],[Owner de la cuenta]]=Table1[[#This Row],[Owner Name]],"Si","No") -> Si | U37: Aguascalientes | V37: SFAC0006091715 | X37: Food Bev & Ag
C38: =VLOOKUP(D38,Diccionario!A:B,2,0) -> LMM 1 | D38: Alejandro Monteón | E38: Meeting | F38: Industria procesadora de empaques | H38: 46078 | I38: Presentación con la Adm para ver posibles proyectos de inversión. | J38: =IF(G38="",F38,G38) -> Industria procesadora de empaques | K38: =IFERROR(VLOOKUP(Table1[[#This Row],[Top Parent]],'1.- Citas sin this week'!G:G,1,0),"New New") -> New New | L38: =_xlfn.XLOOKUP(Table1[[#This Row],[Top Parent]],Table3[Top Parent],Table3[Date]) -> #N/A | M38: =Table1[[#This Row],[Date]]-Table1[[#This Row],[Last Date]] -> #N/A | N38: =_xlfn.XLOOKUP(Table1[[#This Row],[Top Parent]],Table3[Top Parent],Table3[Owner Name]) -> #N/A | P38: Dormant* | Q38: =IF(Table1[[#This Row],[Last Owner]]=Table1[[#This Row],[Owner Name]],"No","Si") -> #N/A | R38: =IF(Table1[[#This Row],[Diferencia de dias]]>182,"Si","No") -> #N/A | S38: Alejandro Monteón | T38: =IF(Table1[[#This Row],[Owner de la cuenta]]=Table1[[#This Row],[Owner Name]],"Si","No") -> Si | U38: Jalisco | V38: SFAC0006076069 | W38: 1 | X38: Industrial Products & Services
C39: =VLOOKUP(D39,Diccionario!A:B,2,0) -> LMM 1 | D39: Juan Villaseñor | E39: Meeting | F39: RANCHO LA MEMORIA | H39: 46079 | I39: Se tiene contacto con Cynthua empresa operando desde el 2015 en la producion agricola de diferentes vegetales la mayoría para exportación a EUA y la ventas en el pais es con empresas grandes como Walmart indica que tiene un nivel de factruracion entre los 50 mdp y 400 mdp refiere tener buen buro no trabaja con gobierno. requieren 3 Nissan Urvan 14 pasajeros con valor de $842,900.00 pesos piden cotizacion en 24 36 y 48 meses | J39: =IF(G39="",F39,G39) -> RANCHO LA MEMORIA | K39: =IFERROR(VLOOKUP(Table1[[#This Row],[Top Parent]],'1.- Citas sin this week'!G:G,1,0),"New New") -> New New | L39: =_xlfn.XLOOKUP(Table1[[#This Row],[Top Parent]],Table3[Top Parent],Table3[Date]) -> #N/A | M39: =Table1[[#This Row],[Date]]-Table1[[#This Row],[Last Date]] -> #N/A | N39: =_xlfn.XLOOKUP(Table1[[#This Row],[Top Parent]],Table3[Top Parent],Table3[Owner Name]) -> #N/A | Q39: =IF(Table1[[#This Row],[Last Owner]]=Table1[[#This Row],[Owner Name]],"No","Si") -> #N/A | R39: =IF(Table1[[#This Row],[Diferencia de dias]]>182,"Si","No") -> #N/A | S39: Juan Villaseñor | T39: =IF(Table1[[#This Row],[Owner de la cuenta]]=Table1[[#This Row],[Owner Name]],"Si","No") -> Si | U39: Sinaloa | V39: SFAC0006110892 | X39: Food Bev & Ag
C40: =VLOOKUP(D40,Diccionario!A:B,2,0) -> LMM 1 | D40: Juan Villaseñor | E40: Meeting | F40: Energio Servicios de Energía Sostenible | H40: 46078 | I40: -Hable con Neto Leal. -CEO de la empresa. -Dedicados a egregia sustentable a nivel industrial. -Interesado en adquirir vehículos para su operación: 3 camionetas pickup, 36 meses, seguro propio y placas en diferentes estados. Y capital de trabajo cuenta con 5 compresores industriales 1.1 MDP cada uno. -Ventas de 100 MDP. -Buen buro. -No trabaja con gobierno. -Mas de 20 años operando. -Ubicados en Sinaloa. | J40: =IF(G40="",F40,G40) -> Energio Servicios de Energía Sostenible | K40: =IFERROR(VLOOKUP(Table1[[#This Row],[Top Parent]],'1.- Citas sin this week'!G:G,1,0),"New New") -> New New | L40: =_xlfn.XLOOKUP(Table1[[#This Row],[Top Parent]],Table3[Top Parent],Table3[Date]) -> #N/A | M40: =Table1[[#This Row],[Date]]-Table1[[#This Row],[Last Date]] -> #N/A | N40: =_xlfn.XLOOKUP(Table1[[#This Row],[Top Parent]],Table3[Top Parent],Table3[Owner Name]) -> #N/A | P40: Prospect | Q40: =IF(Table1[[#This Row],[Last Owner]]=Table1[[#This Row],[Owner Name]],"No","Si") -> #N/A | R40: =IF(Table1[[#This Row],[Diferencia de dias]]>182,"Si","No") -> #N/A | S40: Juan Villaseñor | T40: =IF(Table1[[#This Row],[Owner de la cuenta]]=Table1[[#This Row],[Owner Name]],"Si","No") -> Si | U40: Sinaloa | V40: SFAC0006090100 | X40: Misc Service Industries
...

Sheet 1.- Citas sin this week
A1: Region | B1: Owner Name | C1: Subject | D1: Account Legal Name | E1: Top Parent Account | F1: Date | G1: Top Parent | H1: Account Status
B2: Julieta Medrano | C2: Meeting | D2: CONSORCIO INDUSTRIAL ELIGON | F2: 46073 | G2: =IF(Table3[[#This Row],[Top Parent Account]]="",Table3[[#This Row],[Account Legal Name]],Table3[[#This Row],[Top Parent Account]]) -> CONSORCIO INDUSTRIAL ELIGON
B3: Samuel Cepeda | C3: Meeting | D3: Naturesweet Invernaderos | F3: 46073 | G3: =IF(Table3[[#This Row],[Top Parent Account]]="",Table3[[#This Row],[Account Legal Name]],Table3[[#This Row],[Top Parent Account]]) -> Naturesweet Invernaderos
B4: Alexandra Ramírez | C4: Meeting | D4: LM Minería y Proyectos | F4: 46073 | G4: =IF(Table3[[#This Row],[Top Parent Account]]="",Table3[[#This Row],[Account Legal Name]],Table3[[#This Row],[Top Parent Account]]) -> LM Minería y Proyectos
B5: Rafael Garcia | C5: Meeting | D5: Prefamovil Infraestructura | F5: 46073 | G5: =IF(Table3[[#This Row],[Top Parent Account]]="",Table3[[#This Row],[Account Legal Name]],Table3[[#This Row],[Top Parent Account]]) -> Prefamovil Infraestructura
B6: Josue Olvera | C6: Meeting | D6: PQ Servicios e Infraestructura | F6: 46073 | G6: =IF(Table3[[#This Row],[Top Parent Account]]="",Table3[[#This Row],[Account Legal Name]],Table3[[#This Row],[Top Parent Account]]) -> PQ Servicios e Infraestructura
B7: Ivan Gonzalez | C7: Call | D7: Ladrillera Mecanizada | F7: 46073 | G7: =IF(Table3[[#This Row],[Top Parent Account]]="",Table3[[#This Row],[Account Legal Name]],Table3[[#This Row],[Top Parent Account]]) -> Ladrillera Mecanizada
B8: Josue Olvera | C8: Meeting | D8: Manufacturas Industriales Dp | F8: 46073 | G8: =IF(Table3[[#This Row],[Top Parent Account]]="",Table3[[#This Row],[Account Legal Name]],Table3[[#This Row],[Top Parent Account]]) -> Manufacturas Industriales Dp
B9: Josue Olvera | C9: Meeting | D9: DICOM Fresnillo | F9: 46073 | G9: =IF(Table3[[#This Row],[Top Parent Account]]="",Table3[[#This Row],[Account Legal Name]],Table3[[#This Row],[Top Parent Account]]) -> DICOM Fresnillo
B10: Jose Nava | C10: Meeting | D10: ANOVA AMERICAS INTERNATIONAL COMPANY | F10: 46073 | G10: =IF(Table3[[#This Row],[Top Parent Account]]="",Table3[[#This Row],[Account Legal Name]],Table3[[#This Row],[Top Parent Account]]) -> ANOVA AMERICAS INTERNATIONAL COMPANY
B11: Fernando Martin | C11: Meeting | D11: Evsa | F11: 46073 | G11: =IF(Table3[[#This Row],[Top Parent Account]]="",Table3[[#This Row],[Account Legal Name]],Table3[[#This Row],[Top Parent Account]]) -> Evsa
B12: Moises Villalon | C12: Meeting | D12: Cosmética | F12: 46073 | G12: =IF(Table3[[#This Row],[Top Parent Account]]="",Table3[[#This Row],[Account Legal Name]],Table3[[#This Row],[Top Parent Account]]) -> Cosmética
B13: Josue Olvera | C13: Meeting | D13: Super Farmacias Santa Maria | F13: 46073 | G13: =IF(Table3[[#This Row],[Top Parent Account]]="",Table3[[#This Row],[Account Legal Name]],Table3[[#This Row],[Top Parent Account]]) -> Super Farmacias Santa Maria
B14: Gabriela Lopez | C14: Meeting | D14: IACNA MEXICO II | E14: IACNA MEXICO | F14: 46073 | G14: =IF(Table3[[#This Row],[Top Parent Account]]="",Table3[[#This Row],[Account Legal Name]],Table3[[#This Row],[Top Parent Account]]) -> IACNA MEXICO
B15: Jorge Avendaño | C15: Meeting | D15: Especialistas En Turbopartes División Aeronáutica | E15: Especialistas En Turbopartes | F15: 46073 | G15: =IF(Table3[[#This Row],[Top Parent Account]]="",Table3[[#This Row],[Account Legal Name]],Table3[[#This Row],[Top Parent Account]]) -> Especialistas En Turbopartes
B16: Roberto Anaya | C16: Meeting | D16: Suajes y Empaques | F16: 46073 | G16: =IF(Table3[[#This Row],[Top Parent Account]]="",Table3[[#This Row],[Account Legal Name]],Table3[[#This Row],[Top Parent Account]]) -> Suajes y Empaques
B17: Fernando Carbajal | C17: Meeting | D17: Edificaciones Carver | F17: 46073 | G17: =IF(Table3[[#This Row],[Top Parent Account]]="",Table3[[#This Row],[Account Legal Name]],Table3[[#This Row],[Top Parent Account]]) -> Edificaciones Carver
B18: Armando Estrada | C18: Meeting | D18: Alianza Eléctrica | F18: 46073 | G18: =IF(Table3[[#This Row],[Top Parent Account]]="",Table3[[#This Row],[Account Legal Name]],Table3[[#This Row],[Top Parent Account]]) -> Alianza Eléctrica
B19: Julieta Medrano | C19: Meeting | D19: Oscar Alonso Reynosa Armendariz | F19: 46073 | G19: =IF(Table3[[#This Row],[Top Parent Account]]="",Table3[[#This Row],[Account Legal Name]],Table3[[#This Row],[Top Parent Account]]) -> Oscar Alonso Reynosa Armendariz
B20: Omar Rodríguez | C20: Meeting | D20: Grupo Canels | F20: 46073 | G20: =IF(Table3[[#This Row],[Top Parent Account]]="",Table3[[#This Row],[Account Legal Name]],Table3[[#This Row],[Top Parent Account]]) -> Grupo Canels
B21: Moises Villalon | C21: Meeting | D21: Gluten y Almidones Industriales | F21: 46073 | G21: =IF(Table3[[#This Row],[Top Parent Account]]="",Table3[[#This Row],[Account Legal Name]],Table3[[#This Row],[Top Parent Account]]) -> Gluten y Almidones Industriales
B22: Marco Cohen | C22: Meeting | D22: Siemens | F22: 46073 | G22: =IF(Table3[[#This Row],[Top Parent Account]]="",Table3[[#This Row],[Account Legal Name]],Table3[[#This Row],[Top Parent Account]]) -> Siemens
B23: Jose Nava | C23: Meeting | D23: Planeación de Logística y movilidad | F23: 46073 | G23: =IF(Table3[[#This Row],[Top Parent Account]]="",Table3[[#This Row],[Account Legal Name]],Table3[[#This Row],[Top Parent Account]]) -> Planeación de Logística y movilidad
B24: Jose Nava | C24: Meeting | D24: Refrigerados Maverick | F24: 46073 | G24: =IF(Table3[[#This Row],[Top Parent Account]]="",Table3[[#This Row],[Account Legal Name]],Table3[[#This Row],[Top Parent Account]]) -> Refrigerados Maverick
B25: Jose Nava | C25: Meeting | D25: Alambique de Oro | F25: 46073 | G25: =IF(Table3[[#This Row],[Top Parent Account]]="",Table3[[#This Row],[Account Legal Name]],Table3[[#This Row],[Top Parent Account]]) -> Alambique de Oro
B26: Jose Nava | C26: Meeting | D26: CAJAS Y CORRUGADOS PARA EMPAQUE | F26: 46073 | G26: =IF(Table3[[#This Row],[Top Parent Account]]="",Table3[[#This Row],[Account Legal Name]],Table3[[#This Row],[Top Parent Account]]) -> CAJAS Y CORRUGADOS PARA EMPAQUE
B27: Mauricio Ortiz | C27: Meeting | D27: Enfoque Quimico | F27: 46073 | G27: =IF(Table3[[#This Row],[Top Parent Account]]="",Table3[[#This Row],[Account Legal Name]],Table3[[#This Row],[Top Parent Account]]) -> Enfoque Quimico
... B31: Jose Nava | C31: Meeting | D31: Innovacion Logika En Transporte | F31: 46073 | G31: =IF(Table3[[#This Row],[Top Parent Account]]="",Table3[[#This Row],[Account Legal Name]],Table3[[#This Row],[Top Parent Account]]) -> Innovacion Logika En Transporte
